const f = () => {
  try {
    let a = 0;
    // console.log(program);
    console.log("Programme ranned succesfully");
    return 
  } catch (error) {
    console.log("This is an error");
    console.log(p);


  } 
  finally { /// finally chelega hi chalega !!
    //code hamesa run even catch block mein bhi error aa jae tb ke liye
    console.log("I am a good boy");
    //use cases:
    //close the file
    //exit the loop
    //write to the log file
  }
};

f();